example/prizer_small_out.in
28800758 S 8832.56
28800796 S NA
28800812 S 8832.56
28800974 B 8865.00
28800975 B NA
28812071 S NA
28813129 S 8806.50
28813300 S NA
28813830 B 8845.00
28814087 B 8836.00
28815804 S 8804.25
28815937 B 8845.00
28816245 B 8840.00
